Traceback (most recent call last):
  File "C:\Users\Freyja\AppData\Local\Packages\PythonSoftwareFoundation.Python.3.9_qbz5n2kfra8p0\LocalCache\local-packages\Python39\site-packages\jupyter_cache\executors\utils.py", line 51, in single_nb_execution
    executenb(
  File "C:\Users\Freyja\AppData\Local\Packages\PythonSoftwareFoundation.Python.3.9_qbz5n2kfra8p0\LocalCache\local-packages\Python39\site-packages\nbclient\client.py", line 1112, in execute
    return NotebookClient(nb=nb, resources=resources, km=km, **kwargs).execute()
  File "C:\Users\Freyja\AppData\Local\Packages\PythonSoftwareFoundation.Python.3.9_qbz5n2kfra8p0\LocalCache\local-packages\Python39\site-packages\nbclient\util.py", line 74, in wrapped
    return just_run(coro(*args, **kwargs))
  File "C:\Users\Freyja\AppData\Local\Packages\PythonSoftwareFoundation.Python.3.9_qbz5n2kfra8p0\LocalCache\local-packages\Python39\site-packages\nbclient\util.py", line 53, in just_run
    return loop.run_until_complete(coro)
  File "C:\Program Files\WindowsApps\PythonSoftwareFoundation.Python.3.9_3.9.1776.0_x64__qbz5n2kfra8p0\lib\asyncio\base_events.py", line 642, in run_until_complete
    return future.result()
  File "C:\Users\Freyja\AppData\Local\Packages\PythonSoftwareFoundation.Python.3.9_qbz5n2kfra8p0\LocalCache\local-packages\Python39\site-packages\nbclient\client.py", line 553, in async_execute
    await self.async_execute_cell(
  File "C:\Users\Freyja\AppData\Local\Packages\PythonSoftwareFoundation.Python.3.9_qbz5n2kfra8p0\LocalCache\local-packages\Python39\site-packages\nbclient\client.py", line 857, in async_execute_cell
    self._check_raise_for_error(cell, exec_reply)
  File "C:\Users\Freyja\AppData\Local\Packages\PythonSoftwareFoundation.Python.3.9_qbz5n2kfra8p0\LocalCache\local-packages\Python39\site-packages\nbclient\client.py", line 760, in _check_raise_for_error
    raise CellExecutionError.from_cell_and_msg(cell, exec_reply_content)
nbclient.exceptions.CellExecutionError: An error occurred while executing the following cell:
------------------
# merges dataframes student_assessment with assessments with a full outer join on their common ID id_assessment
# creates a column _merge which tells you if the id_assessment was found in one or both dataframes
merged_assessments = student_assessment.merge(assessments, how='outer', on=['id_assessment'] ,indicator=True)
merged_assessments.head()
------------------

[1;31m---------------------------------------------------------------------------[0m
[1;31mNameError[0m                                 Traceback (most recent call last)
[1;32m~\AppData\Local\Temp/ipykernel_10668/3924523329.py[0m in [0;36m<module>[1;34m[0m
[0;32m      1[0m [1;31m# merges dataframes student_assessment with assessments with a full outer join on their common ID id_assessment[0m[1;33m[0m[1;33m[0m[1;33m[0m[0m
[0;32m      2[0m [1;31m# creates a column _merge which tells you if the id_assessment was found in one or both dataframes[0m[1;33m[0m[1;33m[0m[1;33m[0m[0m
[1;32m----> 3[1;33m [0mmerged_assessments[0m [1;33m=[0m [0mstudent_assessment[0m[1;33m.[0m[0mmerge[0m[1;33m([0m[0massessments[0m[1;33m,[0m [0mhow[0m[1;33m=[0m[1;34m'outer'[0m[1;33m,[0m [0mon[0m[1;33m=[0m[1;33m[[0m[1;34m'id_assessment'[0m[1;33m][0m [1;33m,[0m[0mindicator[0m[1;33m=[0m[1;32mTrue[0m[1;33m)[0m[1;33m[0m[1;33m[0m[0m
[0m[0;32m      4[0m [0mmerged_assessments[0m[1;33m.[0m[0mhead[0m[1;33m([0m[1;33m)[0m[1;33m[0m[1;33m[0m[0m

[1;31mNameError[0m: name 'student_assessment' is not defined
NameError: name 'student_assessment' is not defined

